{
 "cells": [
  {
   "cell_type": "code",
   "execution_count": 2,
   "metadata": {},
   "outputs": [],
   "source": [
    "! huggingface-cli login\n",
    "access_token = \"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\""
   ]
  },
  {
   "cell_type": "code",
   "execution_count": 6,
   "metadata": {},
   "outputs": [
    {
     "ename": "OSError",
     "evalue": "You are trying to access a gated repo.\nMake sure to request access at https://huggingface.co/meta-llama/Llama-2-7b-hf and pass a token having permission to this repo either by logging in with `huggingface-cli login` or by passing `token=<your_token>`.",
     "output_type": "error",
     "traceback": [
      "\u001b[0;31m---------------------------------------------------------------------------\u001b[0m",
      "\u001b[0;31mHTTPError\u001b[0m                                 Traceback (most recent call last)",
      "File \u001b[0;32m~/Documents/source/sandbox/finetune-llm/.venv/lib/python3.10/site-packages/huggingface_hub/utils/_errors.py:261\u001b[0m, in \u001b[0;36mhf_raise_for_status\u001b[0;34m(response, endpoint_name)\u001b[0m\n\u001b[1;32m    260\u001b[0m \u001b[39mtry\u001b[39;00m:\n\u001b[0;32m--> 261\u001b[0m     response\u001b[39m.\u001b[39;49mraise_for_status()\n\u001b[1;32m    262\u001b[0m \u001b[39mexcept\u001b[39;00m HTTPError \u001b[39mas\u001b[39;00m e:\n",
      "File \u001b[0;32m~/Documents/source/sandbox/finetune-llm/.venv/lib/python3.10/site-packages/requests/models.py:1021\u001b[0m, in \u001b[0;36mResponse.raise_for_status\u001b[0;34m(self)\u001b[0m\n\u001b[1;32m   1020\u001b[0m \u001b[39mif\u001b[39;00m http_error_msg:\n\u001b[0;32m-> 1021\u001b[0m     \u001b[39mraise\u001b[39;00m HTTPError(http_error_msg, response\u001b[39m=\u001b[39m\u001b[39mself\u001b[39m)\n",
      "\u001b[0;31mHTTPError\u001b[0m: 403 Client Error: Forbidden for url: https://huggingface.co/meta-llama/Llama-2-7b-hf/resolve/main/config.json",
      "\nThe above exception was the direct cause of the following exception:\n",
      "\u001b[0;31mGatedRepoError\u001b[0m                            Traceback (most recent call last)",
      "File \u001b[0;32m~/Documents/source/sandbox/finetune-llm/.venv/lib/python3.10/site-packages/transformers/utils/hub.py:429\u001b[0m, in \u001b[0;36mcached_file\u001b[0;34m(path_or_repo_id, filename, cache_dir, force_download, resume_download, proxies, token, revision, local_files_only, subfolder, repo_type, user_agent, _raise_exceptions_for_missing_entries, _raise_exceptions_for_connection_errors, _commit_hash, **deprecated_kwargs)\u001b[0m\n\u001b[1;32m    427\u001b[0m \u001b[39mtry\u001b[39;00m:\n\u001b[1;32m    428\u001b[0m     \u001b[39m# Load from URL or cache if already cached\u001b[39;00m\n\u001b[0;32m--> 429\u001b[0m     resolved_file \u001b[39m=\u001b[39m hf_hub_download(\n\u001b[1;32m    430\u001b[0m         path_or_repo_id,\n\u001b[1;32m    431\u001b[0m         filename,\n\u001b[1;32m    432\u001b[0m         subfolder\u001b[39m=\u001b[39;49m\u001b[39mNone\u001b[39;49;00m \u001b[39mif\u001b[39;49;00m \u001b[39mlen\u001b[39;49m(subfolder) \u001b[39m==\u001b[39;49m \u001b[39m0\u001b[39;49m \u001b[39melse\u001b[39;49;00m subfolder,\n\u001b[1;32m    433\u001b[0m         repo_type\u001b[39m=\u001b[39;49mrepo_type,\n\u001b[1;32m    434\u001b[0m         revision\u001b[39m=\u001b[39;49mrevision,\n\u001b[1;32m    435\u001b[0m         cache_dir\u001b[39m=\u001b[39;49mcache_dir,\n\u001b[1;32m    436\u001b[0m         user_agent\u001b[39m=\u001b[39;49muser_agent,\n\u001b[1;32m    437\u001b[0m         force_download\u001b[39m=\u001b[39;49mforce_download,\n\u001b[1;32m    438\u001b[0m         proxies\u001b[39m=\u001b[39;49mproxies,\n\u001b[1;32m    439\u001b[0m         resume_download\u001b[39m=\u001b[39;49mresume_download,\n\u001b[1;32m    440\u001b[0m         token\u001b[39m=\u001b[39;49mtoken,\n\u001b[1;32m    441\u001b[0m         local_files_only\u001b[39m=\u001b[39;49mlocal_files_only,\n\u001b[1;32m    442\u001b[0m     )\n\u001b[1;32m    443\u001b[0m \u001b[39mexcept\u001b[39;00m GatedRepoError \u001b[39mas\u001b[39;00m e:\n",
      "File \u001b[0;32m~/Documents/source/sandbox/finetune-llm/.venv/lib/python3.10/site-packages/huggingface_hub/utils/_validators.py:118\u001b[0m, in \u001b[0;36mvalidate_hf_hub_args.<locals>._inner_fn\u001b[0;34m(*args, **kwargs)\u001b[0m\n\u001b[1;32m    116\u001b[0m     kwargs \u001b[39m=\u001b[39m smoothly_deprecate_use_auth_token(fn_name\u001b[39m=\u001b[39mfn\u001b[39m.\u001b[39m\u001b[39m__name__\u001b[39m, has_token\u001b[39m=\u001b[39mhas_token, kwargs\u001b[39m=\u001b[39mkwargs)\n\u001b[0;32m--> 118\u001b[0m \u001b[39mreturn\u001b[39;00m fn(\u001b[39m*\u001b[39;49margs, \u001b[39m*\u001b[39;49m\u001b[39m*\u001b[39;49mkwargs)\n",
      "File \u001b[0;32m~/Documents/source/sandbox/finetune-llm/.venv/lib/python3.10/site-packages/huggingface_hub/file_download.py:1344\u001b[0m, in \u001b[0;36mhf_hub_download\u001b[0;34m(repo_id, filename, subfolder, repo_type, revision, endpoint, library_name, library_version, cache_dir, local_dir, local_dir_use_symlinks, user_agent, force_download, force_filename, proxies, etag_timeout, resume_download, token, local_files_only, legacy_cache_layout)\u001b[0m\n\u001b[1;32m   1342\u001b[0m \u001b[39melif\u001b[39;00m \u001b[39misinstance\u001b[39m(head_call_error, RepositoryNotFoundError) \u001b[39mor\u001b[39;00m \u001b[39misinstance\u001b[39m(head_call_error, GatedRepoError):\n\u001b[1;32m   1343\u001b[0m     \u001b[39m# Repo not found => let's raise the actual error\u001b[39;00m\n\u001b[0;32m-> 1344\u001b[0m     \u001b[39mraise\u001b[39;00m head_call_error\n\u001b[1;32m   1345\u001b[0m \u001b[39melse\u001b[39;00m:\n\u001b[1;32m   1346\u001b[0m     \u001b[39m# Otherwise: most likely a connection issue or Hub downtime => let's warn the user\u001b[39;00m\n",
      "File \u001b[0;32m~/Documents/source/sandbox/finetune-llm/.venv/lib/python3.10/site-packages/huggingface_hub/file_download.py:1230\u001b[0m, in \u001b[0;36mhf_hub_download\u001b[0;34m(repo_id, filename, subfolder, repo_type, revision, endpoint, library_name, library_version, cache_dir, local_dir, local_dir_use_symlinks, user_agent, force_download, force_filename, proxies, etag_timeout, resume_download, token, local_files_only, legacy_cache_layout)\u001b[0m\n\u001b[1;32m   1229\u001b[0m \u001b[39mtry\u001b[39;00m:\n\u001b[0;32m-> 1230\u001b[0m     metadata \u001b[39m=\u001b[39m get_hf_file_metadata(\n\u001b[1;32m   1231\u001b[0m         url\u001b[39m=\u001b[39;49murl,\n\u001b[1;32m   1232\u001b[0m         token\u001b[39m=\u001b[39;49mtoken,\n\u001b[1;32m   1233\u001b[0m         proxies\u001b[39m=\u001b[39;49mproxies,\n\u001b[1;32m   1234\u001b[0m         timeout\u001b[39m=\u001b[39;49metag_timeout,\n\u001b[1;32m   1235\u001b[0m     )\n\u001b[1;32m   1236\u001b[0m \u001b[39mexcept\u001b[39;00m EntryNotFoundError \u001b[39mas\u001b[39;00m http_error:\n\u001b[1;32m   1237\u001b[0m     \u001b[39m# Cache the non-existence of the file and raise\u001b[39;00m\n",
      "File \u001b[0;32m~/Documents/source/sandbox/finetune-llm/.venv/lib/python3.10/site-packages/huggingface_hub/utils/_validators.py:118\u001b[0m, in \u001b[0;36mvalidate_hf_hub_args.<locals>._inner_fn\u001b[0;34m(*args, **kwargs)\u001b[0m\n\u001b[1;32m    116\u001b[0m     kwargs \u001b[39m=\u001b[39m smoothly_deprecate_use_auth_token(fn_name\u001b[39m=\u001b[39mfn\u001b[39m.\u001b[39m\u001b[39m__name__\u001b[39m, has_token\u001b[39m=\u001b[39mhas_token, kwargs\u001b[39m=\u001b[39mkwargs)\n\u001b[0;32m--> 118\u001b[0m \u001b[39mreturn\u001b[39;00m fn(\u001b[39m*\u001b[39;49margs, \u001b[39m*\u001b[39;49m\u001b[39m*\u001b[39;49mkwargs)\n",
      "File \u001b[0;32m~/Documents/source/sandbox/finetune-llm/.venv/lib/python3.10/site-packages/huggingface_hub/file_download.py:1606\u001b[0m, in \u001b[0;36mget_hf_file_metadata\u001b[0;34m(url, token, proxies, timeout)\u001b[0m\n\u001b[1;32m   1597\u001b[0m r \u001b[39m=\u001b[39m _request_wrapper(\n\u001b[1;32m   1598\u001b[0m     method\u001b[39m=\u001b[39m\u001b[39m\"\u001b[39m\u001b[39mHEAD\u001b[39m\u001b[39m\"\u001b[39m,\n\u001b[1;32m   1599\u001b[0m     url\u001b[39m=\u001b[39murl,\n\u001b[0;32m   (...)\u001b[0m\n\u001b[1;32m   1604\u001b[0m     timeout\u001b[39m=\u001b[39mtimeout,\n\u001b[1;32m   1605\u001b[0m )\n\u001b[0;32m-> 1606\u001b[0m hf_raise_for_status(r)\n\u001b[1;32m   1608\u001b[0m \u001b[39m# Return\u001b[39;00m\n",
      "File \u001b[0;32m~/Documents/source/sandbox/finetune-llm/.venv/lib/python3.10/site-packages/huggingface_hub/utils/_errors.py:277\u001b[0m, in \u001b[0;36mhf_raise_for_status\u001b[0;34m(response, endpoint_name)\u001b[0m\n\u001b[1;32m    274\u001b[0m     message \u001b[39m=\u001b[39m (\n\u001b[1;32m    275\u001b[0m         \u001b[39mf\u001b[39m\u001b[39m\"\u001b[39m\u001b[39m{\u001b[39;00mresponse\u001b[39m.\u001b[39mstatus_code\u001b[39m}\u001b[39;00m\u001b[39m Client Error.\u001b[39m\u001b[39m\"\u001b[39m \u001b[39m+\u001b[39m \u001b[39m\"\u001b[39m\u001b[39m\\n\u001b[39;00m\u001b[39m\\n\u001b[39;00m\u001b[39m\"\u001b[39m \u001b[39m+\u001b[39m \u001b[39mf\u001b[39m\u001b[39m\"\u001b[39m\u001b[39mCannot access gated repo for url \u001b[39m\u001b[39m{\u001b[39;00mresponse\u001b[39m.\u001b[39murl\u001b[39m}\u001b[39;00m\u001b[39m.\u001b[39m\u001b[39m\"\u001b[39m\n\u001b[1;32m    276\u001b[0m     )\n\u001b[0;32m--> 277\u001b[0m     \u001b[39mraise\u001b[39;00m GatedRepoError(message, response) \u001b[39mfrom\u001b[39;00m \u001b[39me\u001b[39;00m\n\u001b[1;32m    279\u001b[0m \u001b[39melif\u001b[39;00m error_code \u001b[39m==\u001b[39m \u001b[39m\"\u001b[39m\u001b[39mRepoNotFound\u001b[39m\u001b[39m\"\u001b[39m \u001b[39mor\u001b[39;00m response\u001b[39m.\u001b[39mstatus_code \u001b[39m==\u001b[39m \u001b[39m401\u001b[39m:\n\u001b[1;32m    280\u001b[0m     \u001b[39m# 401 is misleading as it is returned for:\u001b[39;00m\n\u001b[1;32m    281\u001b[0m     \u001b[39m#    - private and gated repos if user is not authenticated\u001b[39;00m\n\u001b[1;32m    282\u001b[0m     \u001b[39m#    - missing repos\u001b[39;00m\n\u001b[1;32m    283\u001b[0m     \u001b[39m# => for now, we process them as `RepoNotFound` anyway.\u001b[39;00m\n\u001b[1;32m    284\u001b[0m     \u001b[39m# See https://gist.github.com/Wauplin/46c27ad266b15998ce56a6603796f0b9\u001b[39;00m\n",
      "\u001b[0;31mGatedRepoError\u001b[0m: 403 Client Error. (Request ID: Root=1-6502a5db-66d5a4e565d853c1658691d1;f283e5b9-c8e6-4ef5-9eef-189b2f0c4e08)\n\nCannot access gated repo for url https://huggingface.co/meta-llama/Llama-2-7b-hf/resolve/main/config.json.\nYour request to access model meta-llama/Llama-2-7b-hf is awaiting a review from the repo authors.",
      "\nThe above exception was the direct cause of the following exception:\n",
      "\u001b[0;31mOSError\u001b[0m                                   Traceback (most recent call last)",
      "Cell \u001b[0;32mIn[6], line 4\u001b[0m\n\u001b[1;32m      1\u001b[0m \u001b[39m# Use a pipeline as a high-level helper\u001b[39;00m\n\u001b[1;32m      2\u001b[0m \u001b[39mfrom\u001b[39;00m \u001b[39mtransformers\u001b[39;00m \u001b[39mimport\u001b[39;00m pipeline\n\u001b[0;32m----> 4\u001b[0m pipe \u001b[39m=\u001b[39m pipeline(\u001b[39m\"\u001b[39;49m\u001b[39mtext-generation\u001b[39;49m\u001b[39m\"\u001b[39;49m, model\u001b[39m=\u001b[39;49m\u001b[39m\"\u001b[39;49m\u001b[39mmeta-llama/Llama-2-7b-hf\u001b[39;49m\u001b[39m\"\u001b[39;49m)\n",
      "File \u001b[0;32m~/Documents/source/sandbox/finetune-llm/.venv/lib/python3.10/site-packages/transformers/pipelines/__init__.py:741\u001b[0m, in \u001b[0;36mpipeline\u001b[0;34m(task, model, config, tokenizer, feature_extractor, image_processor, framework, revision, use_fast, token, device, device_map, torch_dtype, trust_remote_code, model_kwargs, pipeline_class, **kwargs)\u001b[0m\n\u001b[1;32m    738\u001b[0m                 adapter_config \u001b[39m=\u001b[39m json\u001b[39m.\u001b[39mload(f)\n\u001b[1;32m    739\u001b[0m                 model \u001b[39m=\u001b[39m adapter_config[\u001b[39m\"\u001b[39m\u001b[39mbase_model_name_or_path\u001b[39m\u001b[39m\"\u001b[39m]\n\u001b[0;32m--> 741\u001b[0m     config \u001b[39m=\u001b[39m AutoConfig\u001b[39m.\u001b[39;49mfrom_pretrained(model, _from_pipeline\u001b[39m=\u001b[39;49mtask, \u001b[39m*\u001b[39;49m\u001b[39m*\u001b[39;49mhub_kwargs, \u001b[39m*\u001b[39;49m\u001b[39m*\u001b[39;49mmodel_kwargs)\n\u001b[1;32m    742\u001b[0m     hub_kwargs[\u001b[39m\"\u001b[39m\u001b[39m_commit_hash\u001b[39m\u001b[39m\"\u001b[39m] \u001b[39m=\u001b[39m config\u001b[39m.\u001b[39m_commit_hash\n\u001b[1;32m    744\u001b[0m custom_tasks \u001b[39m=\u001b[39m {}\n",
      "File \u001b[0;32m~/Documents/source/sandbox/finetune-llm/.venv/lib/python3.10/site-packages/transformers/models/auto/configuration_auto.py:1023\u001b[0m, in \u001b[0;36mAutoConfig.from_pretrained\u001b[0;34m(cls, pretrained_model_name_or_path, **kwargs)\u001b[0m\n\u001b[1;32m   1020\u001b[0m revision \u001b[39m=\u001b[39m kwargs\u001b[39m.\u001b[39mpop(\u001b[39m\"\u001b[39m\u001b[39mrevision\u001b[39m\u001b[39m\"\u001b[39m, \u001b[39mNone\u001b[39;00m)\n\u001b[1;32m   1021\u001b[0m kwargs[\u001b[39m\"\u001b[39m\u001b[39mrevision\u001b[39m\u001b[39m\"\u001b[39m] \u001b[39m=\u001b[39m sanitize_code_revision(pretrained_model_name_or_path, revision, trust_remote_code)\n\u001b[0;32m-> 1023\u001b[0m config_dict, unused_kwargs \u001b[39m=\u001b[39m PretrainedConfig\u001b[39m.\u001b[39;49mget_config_dict(pretrained_model_name_or_path, \u001b[39m*\u001b[39;49m\u001b[39m*\u001b[39;49mkwargs)\n\u001b[1;32m   1024\u001b[0m has_remote_code \u001b[39m=\u001b[39m \u001b[39m\"\u001b[39m\u001b[39mauto_map\u001b[39m\u001b[39m\"\u001b[39m \u001b[39min\u001b[39;00m config_dict \u001b[39mand\u001b[39;00m \u001b[39m\"\u001b[39m\u001b[39mAutoConfig\u001b[39m\u001b[39m\"\u001b[39m \u001b[39min\u001b[39;00m config_dict[\u001b[39m\"\u001b[39m\u001b[39mauto_map\u001b[39m\u001b[39m\"\u001b[39m]\n\u001b[1;32m   1025\u001b[0m has_local_code \u001b[39m=\u001b[39m \u001b[39m\"\u001b[39m\u001b[39mmodel_type\u001b[39m\u001b[39m\"\u001b[39m \u001b[39min\u001b[39;00m config_dict \u001b[39mand\u001b[39;00m config_dict[\u001b[39m\"\u001b[39m\u001b[39mmodel_type\u001b[39m\u001b[39m\"\u001b[39m] \u001b[39min\u001b[39;00m CONFIG_MAPPING\n",
      "File \u001b[0;32m~/Documents/source/sandbox/finetune-llm/.venv/lib/python3.10/site-packages/transformers/configuration_utils.py:620\u001b[0m, in \u001b[0;36mPretrainedConfig.get_config_dict\u001b[0;34m(cls, pretrained_model_name_or_path, **kwargs)\u001b[0m\n\u001b[1;32m    618\u001b[0m original_kwargs \u001b[39m=\u001b[39m copy\u001b[39m.\u001b[39mdeepcopy(kwargs)\n\u001b[1;32m    619\u001b[0m \u001b[39m# Get config dict associated with the base config file\u001b[39;00m\n\u001b[0;32m--> 620\u001b[0m config_dict, kwargs \u001b[39m=\u001b[39m \u001b[39mcls\u001b[39;49m\u001b[39m.\u001b[39;49m_get_config_dict(pretrained_model_name_or_path, \u001b[39m*\u001b[39;49m\u001b[39m*\u001b[39;49mkwargs)\n\u001b[1;32m    621\u001b[0m \u001b[39mif\u001b[39;00m \u001b[39m\"\u001b[39m\u001b[39m_commit_hash\u001b[39m\u001b[39m\"\u001b[39m \u001b[39min\u001b[39;00m config_dict:\n\u001b[1;32m    622\u001b[0m     original_kwargs[\u001b[39m\"\u001b[39m\u001b[39m_commit_hash\u001b[39m\u001b[39m\"\u001b[39m] \u001b[39m=\u001b[39m config_dict[\u001b[39m\"\u001b[39m\u001b[39m_commit_hash\u001b[39m\u001b[39m\"\u001b[39m]\n",
      "File \u001b[0;32m~/Documents/source/sandbox/finetune-llm/.venv/lib/python3.10/site-packages/transformers/configuration_utils.py:675\u001b[0m, in \u001b[0;36mPretrainedConfig._get_config_dict\u001b[0;34m(cls, pretrained_model_name_or_path, **kwargs)\u001b[0m\n\u001b[1;32m    671\u001b[0m configuration_file \u001b[39m=\u001b[39m kwargs\u001b[39m.\u001b[39mpop(\u001b[39m\"\u001b[39m\u001b[39m_configuration_file\u001b[39m\u001b[39m\"\u001b[39m, CONFIG_NAME)\n\u001b[1;32m    673\u001b[0m \u001b[39mtry\u001b[39;00m:\n\u001b[1;32m    674\u001b[0m     \u001b[39m# Load from local folder or from cache or download from model Hub and cache\u001b[39;00m\n\u001b[0;32m--> 675\u001b[0m     resolved_config_file \u001b[39m=\u001b[39m cached_file(\n\u001b[1;32m    676\u001b[0m         pretrained_model_name_or_path,\n\u001b[1;32m    677\u001b[0m         configuration_file,\n\u001b[1;32m    678\u001b[0m         cache_dir\u001b[39m=\u001b[39;49mcache_dir,\n\u001b[1;32m    679\u001b[0m         force_download\u001b[39m=\u001b[39;49mforce_download,\n\u001b[1;32m    680\u001b[0m         proxies\u001b[39m=\u001b[39;49mproxies,\n\u001b[1;32m    681\u001b[0m         resume_download\u001b[39m=\u001b[39;49mresume_download,\n\u001b[1;32m    682\u001b[0m         local_files_only\u001b[39m=\u001b[39;49mlocal_files_only,\n\u001b[1;32m    683\u001b[0m         token\u001b[39m=\u001b[39;49mtoken,\n\u001b[1;32m    684\u001b[0m         user_agent\u001b[39m=\u001b[39;49muser_agent,\n\u001b[1;32m    685\u001b[0m         revision\u001b[39m=\u001b[39;49mrevision,\n\u001b[1;32m    686\u001b[0m         subfolder\u001b[39m=\u001b[39;49msubfolder,\n\u001b[1;32m    687\u001b[0m         _commit_hash\u001b[39m=\u001b[39;49mcommit_hash,\n\u001b[1;32m    688\u001b[0m     )\n\u001b[1;32m    689\u001b[0m     commit_hash \u001b[39m=\u001b[39m extract_commit_hash(resolved_config_file, commit_hash)\n\u001b[1;32m    690\u001b[0m \u001b[39mexcept\u001b[39;00m \u001b[39mEnvironmentError\u001b[39;00m:\n\u001b[1;32m    691\u001b[0m     \u001b[39m# Raise any environment error raise by `cached_file`. It will have a helpful error message adapted to\u001b[39;00m\n\u001b[1;32m    692\u001b[0m     \u001b[39m# the original exception.\u001b[39;00m\n",
      "File \u001b[0;32m~/Documents/source/sandbox/finetune-llm/.venv/lib/python3.10/site-packages/transformers/utils/hub.py:444\u001b[0m, in \u001b[0;36mcached_file\u001b[0;34m(path_or_repo_id, filename, cache_dir, force_download, resume_download, proxies, token, revision, local_files_only, subfolder, repo_type, user_agent, _raise_exceptions_for_missing_entries, _raise_exceptions_for_connection_errors, _commit_hash, **deprecated_kwargs)\u001b[0m\n\u001b[1;32m    429\u001b[0m     resolved_file \u001b[39m=\u001b[39m hf_hub_download(\n\u001b[1;32m    430\u001b[0m         path_or_repo_id,\n\u001b[1;32m    431\u001b[0m         filename,\n\u001b[0;32m   (...)\u001b[0m\n\u001b[1;32m    441\u001b[0m         local_files_only\u001b[39m=\u001b[39mlocal_files_only,\n\u001b[1;32m    442\u001b[0m     )\n\u001b[1;32m    443\u001b[0m \u001b[39mexcept\u001b[39;00m GatedRepoError \u001b[39mas\u001b[39;00m e:\n\u001b[0;32m--> 444\u001b[0m     \u001b[39mraise\u001b[39;00m \u001b[39mEnvironmentError\u001b[39;00m(\n\u001b[1;32m    445\u001b[0m         \u001b[39m\"\u001b[39m\u001b[39mYou are trying to access a gated repo.\u001b[39m\u001b[39m\\n\u001b[39;00m\u001b[39mMake sure to request access at \u001b[39m\u001b[39m\"\u001b[39m\n\u001b[1;32m    446\u001b[0m         \u001b[39mf\u001b[39m\u001b[39m\"\u001b[39m\u001b[39mhttps://huggingface.co/\u001b[39m\u001b[39m{\u001b[39;00mpath_or_repo_id\u001b[39m}\u001b[39;00m\u001b[39m and pass a token having permission to this repo either \u001b[39m\u001b[39m\"\u001b[39m\n\u001b[1;32m    447\u001b[0m         \u001b[39m\"\u001b[39m\u001b[39mby logging in with `huggingface-cli login` or by passing `token=<your_token>`.\u001b[39m\u001b[39m\"\u001b[39m\n\u001b[1;32m    448\u001b[0m     ) \u001b[39mfrom\u001b[39;00m \u001b[39me\u001b[39;00m\n\u001b[1;32m    449\u001b[0m \u001b[39mexcept\u001b[39;00m RepositoryNotFoundError \u001b[39mas\u001b[39;00m e:\n\u001b[1;32m    450\u001b[0m     \u001b[39mraise\u001b[39;00m \u001b[39mEnvironmentError\u001b[39;00m(\n\u001b[1;32m    451\u001b[0m         \u001b[39mf\u001b[39m\u001b[39m\"\u001b[39m\u001b[39m{\u001b[39;00mpath_or_repo_id\u001b[39m}\u001b[39;00m\u001b[39m is not a local folder and is not a valid model identifier \u001b[39m\u001b[39m\"\u001b[39m\n\u001b[1;32m    452\u001b[0m         \u001b[39m\"\u001b[39m\u001b[39mlisted on \u001b[39m\u001b[39m'\u001b[39m\u001b[39mhttps://huggingface.co/models\u001b[39m\u001b[39m'\u001b[39m\u001b[39m\\n\u001b[39;00m\u001b[39mIf this is a private repository, make sure to pass a token \u001b[39m\u001b[39m\"\u001b[39m\n\u001b[1;32m    453\u001b[0m         \u001b[39m\"\u001b[39m\u001b[39mhaving permission to this repo either by logging in with `huggingface-cli login` or by passing \u001b[39m\u001b[39m\"\u001b[39m\n\u001b[1;32m    454\u001b[0m         \u001b[39m\"\u001b[39m\u001b[39m`token=<your_token>`\u001b[39m\u001b[39m\"\u001b[39m\n\u001b[1;32m    455\u001b[0m     ) \u001b[39mfrom\u001b[39;00m \u001b[39me\u001b[39;00m\n",
      "\u001b[0;31mOSError\u001b[0m: You are trying to access a gated repo.\nMake sure to request access at https://huggingface.co/meta-llama/Llama-2-7b-hf and pass a token having permission to this repo either by logging in with `huggingface-cli login` or by passing `token=<your_token>`."
     ]
    }
   ],
   "source": [
    "# Use a pipeline as a high-level helper\n",
    "from transformers import pipeline\n",
    "\n",
    "pipe = pipeline(\"text-generation\", model=\"meta-llama/Llama-2-7b-hf\")"
   ]
  },
  {
   "cell_type": "code",
   "execution_count": 3,
   "metadata": {},
   "outputs": [
    {
     "ename": "OSError",
     "evalue": "You are trying to access a gated repo.\nMake sure to request access at https://huggingface.co/meta-llama/Llama-2-7b-hf and pass a token having permission to this repo either by logging in with `huggingface-cli login` or by passing `token=<your_token>`.",
     "output_type": "error",
     "traceback": [
      "\u001b[0;31m---------------------------------------------------------------------------\u001b[0m",
      "\u001b[0;31mHTTPError\u001b[0m                                 Traceback (most recent call last)",
      "File \u001b[0;32m~/Documents/source/sandbox/finetune-llm/.venv/lib/python3.10/site-packages/huggingface_hub/utils/_errors.py:261\u001b[0m, in \u001b[0;36mhf_raise_for_status\u001b[0;34m(response, endpoint_name)\u001b[0m\n\u001b[1;32m    260\u001b[0m \u001b[39mtry\u001b[39;00m:\n\u001b[0;32m--> 261\u001b[0m     response\u001b[39m.\u001b[39;49mraise_for_status()\n\u001b[1;32m    262\u001b[0m \u001b[39mexcept\u001b[39;00m HTTPError \u001b[39mas\u001b[39;00m e:\n",
      "File \u001b[0;32m~/Documents/source/sandbox/finetune-llm/.venv/lib/python3.10/site-packages/requests/models.py:1021\u001b[0m, in \u001b[0;36mResponse.raise_for_status\u001b[0;34m(self)\u001b[0m\n\u001b[1;32m   1020\u001b[0m \u001b[39mif\u001b[39;00m http_error_msg:\n\u001b[0;32m-> 1021\u001b[0m     \u001b[39mraise\u001b[39;00m HTTPError(http_error_msg, response\u001b[39m=\u001b[39m\u001b[39mself\u001b[39m)\n",
      "\u001b[0;31mHTTPError\u001b[0m: 403 Client Error: Forbidden for url: https://huggingface.co/meta-llama/Llama-2-7b-hf/resolve/main/tokenizer_config.json",
      "\nThe above exception was the direct cause of the following exception:\n",
      "\u001b[0;31mGatedRepoError\u001b[0m                            Traceback (most recent call last)",
      "File \u001b[0;32m~/Documents/source/sandbox/finetune-llm/.venv/lib/python3.10/site-packages/transformers/utils/hub.py:429\u001b[0m, in \u001b[0;36mcached_file\u001b[0;34m(path_or_repo_id, filename, cache_dir, force_download, resume_download, proxies, token, revision, local_files_only, subfolder, repo_type, user_agent, _raise_exceptions_for_missing_entries, _raise_exceptions_for_connection_errors, _commit_hash, **deprecated_kwargs)\u001b[0m\n\u001b[1;32m    427\u001b[0m \u001b[39mtry\u001b[39;00m:\n\u001b[1;32m    428\u001b[0m     \u001b[39m# Load from URL or cache if already cached\u001b[39;00m\n\u001b[0;32m--> 429\u001b[0m     resolved_file \u001b[39m=\u001b[39m hf_hub_download(\n\u001b[1;32m    430\u001b[0m         path_or_repo_id,\n\u001b[1;32m    431\u001b[0m         filename,\n\u001b[1;32m    432\u001b[0m         subfolder\u001b[39m=\u001b[39;49m\u001b[39mNone\u001b[39;49;00m \u001b[39mif\u001b[39;49;00m \u001b[39mlen\u001b[39;49m(subfolder) \u001b[39m==\u001b[39;49m \u001b[39m0\u001b[39;49m \u001b[39melse\u001b[39;49;00m subfolder,\n\u001b[1;32m    433\u001b[0m         repo_type\u001b[39m=\u001b[39;49mrepo_type,\n\u001b[1;32m    434\u001b[0m         revision\u001b[39m=\u001b[39;49mrevision,\n\u001b[1;32m    435\u001b[0m         cache_dir\u001b[39m=\u001b[39;49mcache_dir,\n\u001b[1;32m    436\u001b[0m         user_agent\u001b[39m=\u001b[39;49muser_agent,\n\u001b[1;32m    437\u001b[0m         force_download\u001b[39m=\u001b[39;49mforce_download,\n\u001b[1;32m    438\u001b[0m         proxies\u001b[39m=\u001b[39;49mproxies,\n\u001b[1;32m    439\u001b[0m         resume_download\u001b[39m=\u001b[39;49mresume_download,\n\u001b[1;32m    440\u001b[0m         token\u001b[39m=\u001b[39;49mtoken,\n\u001b[1;32m    441\u001b[0m         local_files_only\u001b[39m=\u001b[39;49mlocal_files_only,\n\u001b[1;32m    442\u001b[0m     )\n\u001b[1;32m    443\u001b[0m \u001b[39mexcept\u001b[39;00m GatedRepoError \u001b[39mas\u001b[39;00m e:\n",
      "File \u001b[0;32m~/Documents/source/sandbox/finetune-llm/.venv/lib/python3.10/site-packages/huggingface_hub/utils/_validators.py:118\u001b[0m, in \u001b[0;36mvalidate_hf_hub_args.<locals>._inner_fn\u001b[0;34m(*args, **kwargs)\u001b[0m\n\u001b[1;32m    116\u001b[0m     kwargs \u001b[39m=\u001b[39m smoothly_deprecate_use_auth_token(fn_name\u001b[39m=\u001b[39mfn\u001b[39m.\u001b[39m\u001b[39m__name__\u001b[39m, has_token\u001b[39m=\u001b[39mhas_token, kwargs\u001b[39m=\u001b[39mkwargs)\n\u001b[0;32m--> 118\u001b[0m \u001b[39mreturn\u001b[39;00m fn(\u001b[39m*\u001b[39;49margs, \u001b[39m*\u001b[39;49m\u001b[39m*\u001b[39;49mkwargs)\n",
      "File \u001b[0;32m~/Documents/source/sandbox/finetune-llm/.venv/lib/python3.10/site-packages/huggingface_hub/file_download.py:1344\u001b[0m, in \u001b[0;36mhf_hub_download\u001b[0;34m(repo_id, filename, subfolder, repo_type, revision, endpoint, library_name, library_version, cache_dir, local_dir, local_dir_use_symlinks, user_agent, force_download, force_filename, proxies, etag_timeout, resume_download, token, local_files_only, legacy_cache_layout)\u001b[0m\n\u001b[1;32m   1342\u001b[0m \u001b[39melif\u001b[39;00m \u001b[39misinstance\u001b[39m(head_call_error, RepositoryNotFoundError) \u001b[39mor\u001b[39;00m \u001b[39misinstance\u001b[39m(head_call_error, GatedRepoError):\n\u001b[1;32m   1343\u001b[0m     \u001b[39m# Repo not found => let's raise the actual error\u001b[39;00m\n\u001b[0;32m-> 1344\u001b[0m     \u001b[39mraise\u001b[39;00m head_call_error\n\u001b[1;32m   1345\u001b[0m \u001b[39melse\u001b[39;00m:\n\u001b[1;32m   1346\u001b[0m     \u001b[39m# Otherwise: most likely a connection issue or Hub downtime => let's warn the user\u001b[39;00m\n",
      "File \u001b[0;32m~/Documents/source/sandbox/finetune-llm/.venv/lib/python3.10/site-packages/huggingface_hub/file_download.py:1230\u001b[0m, in \u001b[0;36mhf_hub_download\u001b[0;34m(repo_id, filename, subfolder, repo_type, revision, endpoint, library_name, library_version, cache_dir, local_dir, local_dir_use_symlinks, user_agent, force_download, force_filename, proxies, etag_timeout, resume_download, token, local_files_only, legacy_cache_layout)\u001b[0m\n\u001b[1;32m   1229\u001b[0m \u001b[39mtry\u001b[39;00m:\n\u001b[0;32m-> 1230\u001b[0m     metadata \u001b[39m=\u001b[39m get_hf_file_metadata(\n\u001b[1;32m   1231\u001b[0m         url\u001b[39m=\u001b[39;49murl,\n\u001b[1;32m   1232\u001b[0m         token\u001b[39m=\u001b[39;49mtoken,\n\u001b[1;32m   1233\u001b[0m         proxies\u001b[39m=\u001b[39;49mproxies,\n\u001b[1;32m   1234\u001b[0m         timeout\u001b[39m=\u001b[39;49metag_timeout,\n\u001b[1;32m   1235\u001b[0m     )\n\u001b[1;32m   1236\u001b[0m \u001b[39mexcept\u001b[39;00m EntryNotFoundError \u001b[39mas\u001b[39;00m http_error:\n\u001b[1;32m   1237\u001b[0m     \u001b[39m# Cache the non-existence of the file and raise\u001b[39;00m\n",
      "File \u001b[0;32m~/Documents/source/sandbox/finetune-llm/.venv/lib/python3.10/site-packages/huggingface_hub/utils/_validators.py:118\u001b[0m, in \u001b[0;36mvalidate_hf_hub_args.<locals>._inner_fn\u001b[0;34m(*args, **kwargs)\u001b[0m\n\u001b[1;32m    116\u001b[0m     kwargs \u001b[39m=\u001b[39m smoothly_deprecate_use_auth_token(fn_name\u001b[39m=\u001b[39mfn\u001b[39m.\u001b[39m\u001b[39m__name__\u001b[39m, has_token\u001b[39m=\u001b[39mhas_token, kwargs\u001b[39m=\u001b[39mkwargs)\n\u001b[0;32m--> 118\u001b[0m \u001b[39mreturn\u001b[39;00m fn(\u001b[39m*\u001b[39;49margs, \u001b[39m*\u001b[39;49m\u001b[39m*\u001b[39;49mkwargs)\n",
      "File \u001b[0;32m~/Documents/source/sandbox/finetune-llm/.venv/lib/python3.10/site-packages/huggingface_hub/file_download.py:1606\u001b[0m, in \u001b[0;36mget_hf_file_metadata\u001b[0;34m(url, token, proxies, timeout)\u001b[0m\n\u001b[1;32m   1597\u001b[0m r \u001b[39m=\u001b[39m _request_wrapper(\n\u001b[1;32m   1598\u001b[0m     method\u001b[39m=\u001b[39m\u001b[39m\"\u001b[39m\u001b[39mHEAD\u001b[39m\u001b[39m\"\u001b[39m,\n\u001b[1;32m   1599\u001b[0m     url\u001b[39m=\u001b[39murl,\n\u001b[0;32m   (...)\u001b[0m\n\u001b[1;32m   1604\u001b[0m     timeout\u001b[39m=\u001b[39mtimeout,\n\u001b[1;32m   1605\u001b[0m )\n\u001b[0;32m-> 1606\u001b[0m hf_raise_for_status(r)\n\u001b[1;32m   1608\u001b[0m \u001b[39m# Return\u001b[39;00m\n",
      "File \u001b[0;32m~/Documents/source/sandbox/finetune-llm/.venv/lib/python3.10/site-packages/huggingface_hub/utils/_errors.py:277\u001b[0m, in \u001b[0;36mhf_raise_for_status\u001b[0;34m(response, endpoint_name)\u001b[0m\n\u001b[1;32m    274\u001b[0m     message \u001b[39m=\u001b[39m (\n\u001b[1;32m    275\u001b[0m         \u001b[39mf\u001b[39m\u001b[39m\"\u001b[39m\u001b[39m{\u001b[39;00mresponse\u001b[39m.\u001b[39mstatus_code\u001b[39m}\u001b[39;00m\u001b[39m Client Error.\u001b[39m\u001b[39m\"\u001b[39m \u001b[39m+\u001b[39m \u001b[39m\"\u001b[39m\u001b[39m\\n\u001b[39;00m\u001b[39m\\n\u001b[39;00m\u001b[39m\"\u001b[39m \u001b[39m+\u001b[39m \u001b[39mf\u001b[39m\u001b[39m\"\u001b[39m\u001b[39mCannot access gated repo for url \u001b[39m\u001b[39m{\u001b[39;00mresponse\u001b[39m.\u001b[39murl\u001b[39m}\u001b[39;00m\u001b[39m.\u001b[39m\u001b[39m\"\u001b[39m\n\u001b[1;32m    276\u001b[0m     )\n\u001b[0;32m--> 277\u001b[0m     \u001b[39mraise\u001b[39;00m GatedRepoError(message, response) \u001b[39mfrom\u001b[39;00m \u001b[39me\u001b[39;00m\n\u001b[1;32m    279\u001b[0m \u001b[39melif\u001b[39;00m error_code \u001b[39m==\u001b[39m \u001b[39m\"\u001b[39m\u001b[39mRepoNotFound\u001b[39m\u001b[39m\"\u001b[39m \u001b[39mor\u001b[39;00m response\u001b[39m.\u001b[39mstatus_code \u001b[39m==\u001b[39m \u001b[39m401\u001b[39m:\n\u001b[1;32m    280\u001b[0m     \u001b[39m# 401 is misleading as it is returned for:\u001b[39;00m\n\u001b[1;32m    281\u001b[0m     \u001b[39m#    - private and gated repos if user is not authenticated\u001b[39;00m\n\u001b[1;32m    282\u001b[0m     \u001b[39m#    - missing repos\u001b[39;00m\n\u001b[1;32m    283\u001b[0m     \u001b[39m# => for now, we process them as `RepoNotFound` anyway.\u001b[39;00m\n\u001b[1;32m    284\u001b[0m     \u001b[39m# See https://gist.github.com/Wauplin/46c27ad266b15998ce56a6603796f0b9\u001b[39;00m\n",
      "\u001b[0;31mGatedRepoError\u001b[0m: 403 Client Error. (Request ID: Root=1-6502a47c-51cfaa98009f9e4f0a03782f;4ef3a05c-287b-43a1-ad0c-ae7c1bfb2cb3)\n\nCannot access gated repo for url https://huggingface.co/meta-llama/Llama-2-7b-hf/resolve/main/tokenizer_config.json.\nAccess to model meta-llama/Llama-2-7b-hf is restricted and you are not in the authorized list. Visit https://huggingface.co/meta-llama/Llama-2-7b-hf to ask for access.",
      "\nThe above exception was the direct cause of the following exception:\n",
      "\u001b[0;31mOSError\u001b[0m                                   Traceback (most recent call last)",
      "Cell \u001b[0;32mIn[3], line 4\u001b[0m\n\u001b[1;32m      1\u001b[0m \u001b[39m# Load model directly\u001b[39;00m\n\u001b[1;32m      2\u001b[0m \u001b[39mfrom\u001b[39;00m \u001b[39mtransformers\u001b[39;00m \u001b[39mimport\u001b[39;00m AutoTokenizer, AutoModelForCausalLM\n\u001b[0;32m----> 4\u001b[0m tokenizer \u001b[39m=\u001b[39m AutoTokenizer\u001b[39m.\u001b[39;49mfrom_pretrained(\u001b[39m\"\u001b[39;49m\u001b[39mmeta-llama/Llama-2-7b-hf\u001b[39;49m\u001b[39m\"\u001b[39;49m, token\u001b[39m=\u001b[39;49maccess_token)\n\u001b[1;32m      5\u001b[0m model \u001b[39m=\u001b[39m AutoModelForCausalLM\u001b[39m.\u001b[39mfrom_pretrained(\u001b[39m\"\u001b[39m\u001b[39mmeta-llama/Llama-2-7b-hf\u001b[39m\u001b[39m\"\u001b[39m, token\u001b[39m=\u001b[39maccess_token)\n",
      "File \u001b[0;32m~/Documents/source/sandbox/finetune-llm/.venv/lib/python3.10/site-packages/transformers/models/auto/tokenization_auto.py:686\u001b[0m, in \u001b[0;36mAutoTokenizer.from_pretrained\u001b[0;34m(cls, pretrained_model_name_or_path, *inputs, **kwargs)\u001b[0m\n\u001b[1;32m    683\u001b[0m     \u001b[39mreturn\u001b[39;00m tokenizer_class\u001b[39m.\u001b[39mfrom_pretrained(pretrained_model_name_or_path, \u001b[39m*\u001b[39minputs, \u001b[39m*\u001b[39m\u001b[39m*\u001b[39mkwargs)\n\u001b[1;32m    685\u001b[0m \u001b[39m# Next, let's try to use the tokenizer_config file to get the tokenizer class.\u001b[39;00m\n\u001b[0;32m--> 686\u001b[0m tokenizer_config \u001b[39m=\u001b[39m get_tokenizer_config(pretrained_model_name_or_path, \u001b[39m*\u001b[39;49m\u001b[39m*\u001b[39;49mkwargs)\n\u001b[1;32m    687\u001b[0m \u001b[39mif\u001b[39;00m \u001b[39m\"\u001b[39m\u001b[39m_commit_hash\u001b[39m\u001b[39m\"\u001b[39m \u001b[39min\u001b[39;00m tokenizer_config:\n\u001b[1;32m    688\u001b[0m     kwargs[\u001b[39m\"\u001b[39m\u001b[39m_commit_hash\u001b[39m\u001b[39m\"\u001b[39m] \u001b[39m=\u001b[39m tokenizer_config[\u001b[39m\"\u001b[39m\u001b[39m_commit_hash\u001b[39m\u001b[39m\"\u001b[39m]\n",
      "File \u001b[0;32m~/Documents/source/sandbox/finetune-llm/.venv/lib/python3.10/site-packages/transformers/models/auto/tokenization_auto.py:519\u001b[0m, in \u001b[0;36mget_tokenizer_config\u001b[0;34m(pretrained_model_name_or_path, cache_dir, force_download, resume_download, proxies, token, revision, local_files_only, subfolder, **kwargs)\u001b[0m\n\u001b[1;32m    516\u001b[0m     token \u001b[39m=\u001b[39m use_auth_token\n\u001b[1;32m    518\u001b[0m commit_hash \u001b[39m=\u001b[39m kwargs\u001b[39m.\u001b[39mget(\u001b[39m\"\u001b[39m\u001b[39m_commit_hash\u001b[39m\u001b[39m\"\u001b[39m, \u001b[39mNone\u001b[39;00m)\n\u001b[0;32m--> 519\u001b[0m resolved_config_file \u001b[39m=\u001b[39m cached_file(\n\u001b[1;32m    520\u001b[0m     pretrained_model_name_or_path,\n\u001b[1;32m    521\u001b[0m     TOKENIZER_CONFIG_FILE,\n\u001b[1;32m    522\u001b[0m     cache_dir\u001b[39m=\u001b[39;49mcache_dir,\n\u001b[1;32m    523\u001b[0m     force_download\u001b[39m=\u001b[39;49mforce_download,\n\u001b[1;32m    524\u001b[0m     resume_download\u001b[39m=\u001b[39;49mresume_download,\n\u001b[1;32m    525\u001b[0m     proxies\u001b[39m=\u001b[39;49mproxies,\n\u001b[1;32m    526\u001b[0m     token\u001b[39m=\u001b[39;49mtoken,\n\u001b[1;32m    527\u001b[0m     revision\u001b[39m=\u001b[39;49mrevision,\n\u001b[1;32m    528\u001b[0m     local_files_only\u001b[39m=\u001b[39;49mlocal_files_only,\n\u001b[1;32m    529\u001b[0m     subfolder\u001b[39m=\u001b[39;49msubfolder,\n\u001b[1;32m    530\u001b[0m     _raise_exceptions_for_missing_entries\u001b[39m=\u001b[39;49m\u001b[39mFalse\u001b[39;49;00m,\n\u001b[1;32m    531\u001b[0m     _raise_exceptions_for_connection_errors\u001b[39m=\u001b[39;49m\u001b[39mFalse\u001b[39;49;00m,\n\u001b[1;32m    532\u001b[0m     _commit_hash\u001b[39m=\u001b[39;49mcommit_hash,\n\u001b[1;32m    533\u001b[0m )\n\u001b[1;32m    534\u001b[0m \u001b[39mif\u001b[39;00m resolved_config_file \u001b[39mis\u001b[39;00m \u001b[39mNone\u001b[39;00m:\n\u001b[1;32m    535\u001b[0m     logger\u001b[39m.\u001b[39minfo(\u001b[39m\"\u001b[39m\u001b[39mCould not locate the tokenizer configuration file, will try to use the model config instead.\u001b[39m\u001b[39m\"\u001b[39m)\n",
      "File \u001b[0;32m~/Documents/source/sandbox/finetune-llm/.venv/lib/python3.10/site-packages/transformers/utils/hub.py:444\u001b[0m, in \u001b[0;36mcached_file\u001b[0;34m(path_or_repo_id, filename, cache_dir, force_download, resume_download, proxies, token, revision, local_files_only, subfolder, repo_type, user_agent, _raise_exceptions_for_missing_entries, _raise_exceptions_for_connection_errors, _commit_hash, **deprecated_kwargs)\u001b[0m\n\u001b[1;32m    429\u001b[0m     resolved_file \u001b[39m=\u001b[39m hf_hub_download(\n\u001b[1;32m    430\u001b[0m         path_or_repo_id,\n\u001b[1;32m    431\u001b[0m         filename,\n\u001b[0;32m   (...)\u001b[0m\n\u001b[1;32m    441\u001b[0m         local_files_only\u001b[39m=\u001b[39mlocal_files_only,\n\u001b[1;32m    442\u001b[0m     )\n\u001b[1;32m    443\u001b[0m \u001b[39mexcept\u001b[39;00m GatedRepoError \u001b[39mas\u001b[39;00m e:\n\u001b[0;32m--> 444\u001b[0m     \u001b[39mraise\u001b[39;00m \u001b[39mEnvironmentError\u001b[39;00m(\n\u001b[1;32m    445\u001b[0m         \u001b[39m\"\u001b[39m\u001b[39mYou are trying to access a gated repo.\u001b[39m\u001b[39m\\n\u001b[39;00m\u001b[39mMake sure to request access at \u001b[39m\u001b[39m\"\u001b[39m\n\u001b[1;32m    446\u001b[0m         \u001b[39mf\u001b[39m\u001b[39m\"\u001b[39m\u001b[39mhttps://huggingface.co/\u001b[39m\u001b[39m{\u001b[39;00mpath_or_repo_id\u001b[39m}\u001b[39;00m\u001b[39m and pass a token having permission to this repo either \u001b[39m\u001b[39m\"\u001b[39m\n\u001b[1;32m    447\u001b[0m         \u001b[39m\"\u001b[39m\u001b[39mby logging in with `huggingface-cli login` or by passing `token=<your_token>`.\u001b[39m\u001b[39m\"\u001b[39m\n\u001b[1;32m    448\u001b[0m     ) \u001b[39mfrom\u001b[39;00m \u001b[39me\u001b[39;00m\n\u001b[1;32m    449\u001b[0m \u001b[39mexcept\u001b[39;00m RepositoryNotFoundError \u001b[39mas\u001b[39;00m e:\n\u001b[1;32m    450\u001b[0m     \u001b[39mraise\u001b[39;00m \u001b[39mEnvironmentError\u001b[39;00m(\n\u001b[1;32m    451\u001b[0m         \u001b[39mf\u001b[39m\u001b[39m\"\u001b[39m\u001b[39m{\u001b[39;00mpath_or_repo_id\u001b[39m}\u001b[39;00m\u001b[39m is not a local folder and is not a valid model identifier \u001b[39m\u001b[39m\"\u001b[39m\n\u001b[1;32m    452\u001b[0m         \u001b[39m\"\u001b[39m\u001b[39mlisted on \u001b[39m\u001b[39m'\u001b[39m\u001b[39mhttps://huggingface.co/models\u001b[39m\u001b[39m'\u001b[39m\u001b[39m\\n\u001b[39;00m\u001b[39mIf this is a private repository, make sure to pass a token \u001b[39m\u001b[39m\"\u001b[39m\n\u001b[1;32m    453\u001b[0m         \u001b[39m\"\u001b[39m\u001b[39mhaving permission to this repo either by logging in with `huggingface-cli login` or by passing \u001b[39m\u001b[39m\"\u001b[39m\n\u001b[1;32m    454\u001b[0m         \u001b[39m\"\u001b[39m\u001b[39m`token=<your_token>`\u001b[39m\u001b[39m\"\u001b[39m\n\u001b[1;32m    455\u001b[0m     ) \u001b[39mfrom\u001b[39;00m \u001b[39me\u001b[39;00m\n",
      "\u001b[0;31mOSError\u001b[0m: You are trying to access a gated repo.\nMake sure to request access at https://huggingface.co/meta-llama/Llama-2-7b-hf and pass a token having permission to this repo either by logging in with `huggingface-cli login` or by passing `token=<your_token>`."
     ]
    }
   ],
   "source": [
    "# Load model directly\n",
    "from transformers import AutoTokenizer, AutoModelForCausalLM\n",
    "\n",
    "tokenizer = AutoTokenizer.from_pretrained(\"meta-llama/Llama-2-7b-hf\", token=access_token)\n",
    "model = AutoModelForCausalLM.from_pretrained(\"meta-llama/Llama-2-7b-hf\", token=access_token)"
   ]
  }
 ],
 "metadata": {
  "kernelspec": {
   "display_name": ".venv",
   "language": "python",
   "name": "python3"
  },
  "language_info": {
   "codemirror_mode": {
    "name": "ipython",
    "version": 3
   },
   "file_extension": ".py",
   "mimetype": "text/x-python",
   "name": "python",
   "nbconvert_exporter": "python",
   "pygments_lexer": "ipython3",
   "version": "3.10.13"
  },
  "orig_nbformat": 4
 },
 "nbformat": 4,
 "nbformat_minor": 2
}
